[2025-02-25T02:21:32.857+0000] {local_task_job_runner.py:120} INFO - ::group::Pre task execution logs
[2025-02-25T02:21:32.966+0000] {taskinstance.py:2073} INFO - Dependencies all met for dep_context=non-requeueable deps ti=<TaskInstance: upload_bronze.upload_bronze manual__2025-02-25T02:21:19.509170+00:00 [queued]>
[2025-02-25T02:21:32.976+0000] {taskinstance.py:2073} INFO - Dependencies all met for dep_context=requeueable deps ti=<TaskInstance: upload_bronze.upload_bronze manual__2025-02-25T02:21:19.509170+00:00 [queued]>
[2025-02-25T02:21:32.977+0000] {taskinstance.py:2303} INFO - Starting attempt 1 of 6
[2025-02-25T02:21:33.000+0000] {taskinstance.py:2327} INFO - Executing <Task(PythonOperator): upload_bronze> on 2025-02-25 02:21:19.509170+00:00
[2025-02-25T02:21:33.013+0000] {warnings.py:110} WARNING - /home/***/.local/lib/python3.12/site-packages/***/task/task_runner/standard_task_runner.py:61: DeprecationWarning: This process (pid=1871) is multi-threaded, use of fork() may lead to deadlocks in the child.
  pid = os.fork()

[2025-02-25T02:21:33.014+0000] {standard_task_runner.py:90} INFO - Running: ['***', 'tasks', 'run', 'upload_bronze', 'upload_bronze', 'manual__2025-02-25T02:21:19.509170+00:00', '--job-id', '93', '--raw', '--subdir', 'DAGS_FOLDER/Dag_des_5.py', '--cfg-path', '/tmp/tmpw9sa7j4y']
[2025-02-25T02:21:33.016+0000] {standard_task_runner.py:63} INFO - Started process 1873 to run task
[2025-02-25T02:21:33.019+0000] {standard_task_runner.py:91} INFO - Job 93: Subtask upload_bronze
[2025-02-25T02:21:33.081+0000] {task_command.py:426} INFO - Running <TaskInstance: upload_bronze.upload_bronze manual__2025-02-25T02:21:19.509170+00:00 [running]> on host c37e8af922b1
[2025-02-25T02:21:34.186+0000] {taskinstance.py:2644} INFO - Exporting env vars: AIRFLOW_CTX_DAG_OWNER='***' AIRFLOW_CTX_DAG_ID='upload_bronze' AIRFLOW_CTX_TASK_ID='upload_bronze' AIRFLOW_CTX_EXECUTION_DATE='2025-02-25T02:21:19.509170+00:00' AIRFLOW_CTX_TRY_NUMBER='1' AIRFLOW_CTX_DAG_RUN_ID='manual__2025-02-25T02:21:19.509170+00:00'
[2025-02-25T02:21:34.188+0000] {taskinstance.py:430} INFO - ::endgroup::
[2025-02-25T02:21:34.215+0000] {taskinstance.py:441} INFO - ::group::Post task execution logs
[2025-02-25T02:21:34.216+0000] {taskinstance.py:2890} ERROR - Task failed with exception
Traceback (most recent call last):
  File "/home/airflow/.local/lib/python3.12/site-packages/airflow/models/taskinstance.py", line 465, in _execute_task
    result = _execute_callable(context=context, **execute_callable_kwargs)
             ^^^^^^^^^^^^^^^^^^^^^^^^^^^^^^^^^^^^^^^^^^^^^^^^^^^^^^^^^^^^^
  File "/home/airflow/.local/lib/python3.12/site-packages/airflow/models/taskinstance.py", line 432, in _execute_callable
    return execute_callable(context=context, **execute_callable_kwargs)
           ^^^^^^^^^^^^^^^^^^^^^^^^^^^^^^^^^^^^^^^^^^^^^^^^^^^^^^^^^^^^
  File "/home/airflow/.local/lib/python3.12/site-packages/airflow/models/baseoperator.py", line 400, in wrapper
    return func(self, *args, **kwargs)
           ^^^^^^^^^^^^^^^^^^^^^^^^^^^
  File "/home/airflow/.local/lib/python3.12/site-packages/airflow/operators/python.py", line 235, in execute
    return_value = self.execute_callable()
                   ^^^^^^^^^^^^^^^^^^^^^^^
  File "/home/airflow/.local/lib/python3.12/site-packages/airflow/operators/python.py", line 252, in execute_callable
    return self.python_callable(*self.op_args, **self.op_kwargs)
           ^^^^^^^^^^^^^^^^^^^^^^^^^^^^^^^^^^^^^^^^^^^^^^^^^^^^^
  File "/opt/airflow/dags/app/upload_bronze.py", line 8, in upload_bronze
    for file in os.listdir(INPUT_DIR):
                ^^^^^^^^^^^^^^^^^^^^^
FileNotFoundError: [Errno 2] No such file or directory: '/home/usuario/Documentos/Data sc/Des_5/RID-156732_Desafio08/Dados'
[2025-02-25T02:21:34.257+0000] {taskinstance.py:1205} INFO - Marking task as UP_FOR_RETRY. dag_id=upload_bronze, task_id=upload_bronze, execution_date=20250225T022119, start_date=20250225T022132, end_date=20250225T022134
[2025-02-25T02:21:34.279+0000] {standard_task_runner.py:110} ERROR - Failed to execute job 93 for task upload_bronze ([Errno 2] No such file or directory: '/home/usuario/Documentos/Data sc/Des_5/RID-156732_Desafio08/Dados'; 1873)
[2025-02-25T02:21:34.322+0000] {local_task_job_runner.py:240} INFO - Task exited with return code 1
[2025-02-25T02:21:34.350+0000] {taskinstance.py:3482} INFO - 0 downstream tasks scheduled from follow-on schedule check
[2025-02-25T02:21:34.354+0000] {local_task_job_runner.py:222} INFO - ::endgroup::
