[2025-02-26T01:35:24.210+0000] {local_task_job_runner.py:120} INFO - ::group::Pre task execution logs
[2025-02-26T01:35:24.257+0000] {taskinstance.py:2073} INFO - Dependencies all met for dep_context=non-requeueable deps ti=<TaskInstance: upload_bronze.upload_bronze scheduled__2025-02-25T00:00:00+00:00 [queued]>
[2025-02-26T01:35:24.264+0000] {taskinstance.py:2073} INFO - Dependencies all met for dep_context=requeueable deps ti=<TaskInstance: upload_bronze.upload_bronze scheduled__2025-02-25T00:00:00+00:00 [queued]>
[2025-02-26T01:35:24.265+0000] {taskinstance.py:2303} INFO - Starting attempt 2 of 6
[2025-02-26T01:35:24.279+0000] {taskinstance.py:2327} INFO - Executing <Task(PythonOperator): upload_bronze> on 2025-02-25 00:00:00+00:00
[2025-02-26T01:35:24.286+0000] {warnings.py:110} WARNING - /home/***/.local/lib/python3.12/site-packages/***/task/task_runner/standard_task_runner.py:61: DeprecationWarning: This process (pid=290) is multi-threaded, use of fork() may lead to deadlocks in the child.
  pid = os.fork()

[2025-02-26T01:35:24.288+0000] {standard_task_runner.py:63} INFO - Started process 292 to run task
[2025-02-26T01:35:24.287+0000] {standard_task_runner.py:90} INFO - Running: ['***', 'tasks', 'run', 'upload_bronze', 'upload_bronze', 'scheduled__2025-02-25T00:00:00+00:00', '--job-id', '247', '--raw', '--subdir', 'DAGS_FOLDER/Dag_des_5.py', '--cfg-path', '/tmp/tmp2gogq3c_']
[2025-02-26T01:35:24.289+0000] {standard_task_runner.py:91} INFO - Job 247: Subtask upload_bronze
[2025-02-26T01:35:24.362+0000] {task_command.py:426} INFO - Running <TaskInstance: upload_bronze.upload_bronze scheduled__2025-02-25T00:00:00+00:00 [running]> on host c37e8af922b1
[2025-02-26T01:35:24.462+0000] {taskinstance.py:2644} INFO - Exporting env vars: AIRFLOW_CTX_DAG_OWNER='***' AIRFLOW_CTX_DAG_ID='upload_bronze' AIRFLOW_CTX_TASK_ID='upload_bronze' AIRFLOW_CTX_EXECUTION_DATE='2025-02-25T00:00:00+00:00' AIRFLOW_CTX_TRY_NUMBER='2' AIRFLOW_CTX_DAG_RUN_ID='scheduled__2025-02-25T00:00:00+00:00'
[2025-02-26T01:35:24.464+0000] {taskinstance.py:430} INFO - ::endgroup::
[2025-02-26T01:35:24.466+0000] {taskinstance.py:441} INFO - ::group::Post task execution logs
[2025-02-26T01:35:24.469+0000] {taskinstance.py:2890} ERROR - Task failed with exception
Traceback (most recent call last):
  File "/home/airflow/.local/lib/python3.12/site-packages/airflow/models/taskinstance.py", line 465, in _execute_task
    result = _execute_callable(context=context, **execute_callable_kwargs)
             ^^^^^^^^^^^^^^^^^^^^^^^^^^^^^^^^^^^^^^^^^^^^^^^^^^^^^^^^^^^^^
  File "/home/airflow/.local/lib/python3.12/site-packages/airflow/models/taskinstance.py", line 432, in _execute_callable
    return execute_callable(context=context, **execute_callable_kwargs)
           ^^^^^^^^^^^^^^^^^^^^^^^^^^^^^^^^^^^^^^^^^^^^^^^^^^^^^^^^^^^^
  File "/home/airflow/.local/lib/python3.12/site-packages/airflow/models/baseoperator.py", line 400, in wrapper
    return func(self, *args, **kwargs)
           ^^^^^^^^^^^^^^^^^^^^^^^^^^^
  File "/home/airflow/.local/lib/python3.12/site-packages/airflow/operators/python.py", line 235, in execute
    return_value = self.execute_callable()
                   ^^^^^^^^^^^^^^^^^^^^^^^
  File "/home/airflow/.local/lib/python3.12/site-packages/airflow/operators/python.py", line 252, in execute_callable
    return self.python_callable(*self.op_args, **self.op_kwargs)
           ^^^^^^^^^^^^^^^^^^^^^^^^^^^^^^^^^^^^^^^^^^^^^^^^^^^^^
  File "/opt/airflow/dags/app/upload_bronze.py", line 8, in upload_bronze
    for file in os.listdir(INPUT_DIR):
                ^^^^^^^^^^^^^^^^^^^^^
FileNotFoundError: [Errno 2] No such file or directory: '/mnt/c/Users/Caio Mesquita/Desktop/Data sc/Des_5/RID-156732_Desafio08/Dados'
[2025-02-26T01:35:24.503+0000] {taskinstance.py:1205} INFO - Marking task as UP_FOR_RETRY. dag_id=upload_bronze, task_id=upload_bronze, execution_date=20250225T000000, start_date=20250226T013524, end_date=20250226T013524
[2025-02-26T01:35:24.517+0000] {standard_task_runner.py:110} ERROR - Failed to execute job 247 for task upload_bronze ([Errno 2] No such file or directory: '/mnt/c/Users/Caio Mesquita/Desktop/Data sc/Des_5/RID-156732_Desafio08/Dados'; 292)
[2025-02-26T01:35:24.545+0000] {local_task_job_runner.py:240} INFO - Task exited with return code 1
[2025-02-26T01:35:24.569+0000] {taskinstance.py:3482} INFO - 0 downstream tasks scheduled from follow-on schedule check
[2025-02-26T01:35:24.572+0000] {local_task_job_runner.py:222} INFO - ::endgroup::
