[2025-02-25T02:26:00.937+0000] {local_task_job_runner.py:120} INFO - ::group::Pre task execution logs
[2025-02-25T02:26:00.974+0000] {taskinstance.py:2073} INFO - Dependencies all met for dep_context=non-requeueable deps ti=<TaskInstance: upload_bronze.upload_bronze manual__2025-02-25T02:00:32.574902+00:00 [queued]>
[2025-02-25T02:26:00.984+0000] {taskinstance.py:2073} INFO - Dependencies all met for dep_context=requeueable deps ti=<TaskInstance: upload_bronze.upload_bronze manual__2025-02-25T02:00:32.574902+00:00 [queued]>
[2025-02-25T02:26:00.985+0000] {taskinstance.py:2303} INFO - Starting attempt 6 of 6
[2025-02-25T02:26:01.004+0000] {taskinstance.py:2327} INFO - Executing <Task(PythonOperator): upload_bronze> on 2025-02-25 02:00:32.574902+00:00
[2025-02-25T02:26:01.020+0000] {warnings.py:110} WARNING - /home/***/.local/lib/python3.12/site-packages/***/task/task_runner/standard_task_runner.py:61: DeprecationWarning: This process (pid=1899) is multi-threaded, use of fork() may lead to deadlocks in the child.
  pid = os.fork()

[2025-02-25T02:26:01.021+0000] {standard_task_runner.py:90} INFO - Running: ['***', 'tasks', 'run', 'upload_bronze', 'upload_bronze', 'manual__2025-02-25T02:00:32.574902+00:00', '--job-id', '95', '--raw', '--subdir', 'DAGS_FOLDER/Dag_des_5.py', '--cfg-path', '/tmp/tmp3cte34tn']
[2025-02-25T02:26:01.022+0000] {standard_task_runner.py:63} INFO - Started process 1901 to run task
[2025-02-25T02:26:01.023+0000] {standard_task_runner.py:91} INFO - Job 95: Subtask upload_bronze
[2025-02-25T02:26:01.076+0000] {task_command.py:426} INFO - Running <TaskInstance: upload_bronze.upload_bronze manual__2025-02-25T02:00:32.574902+00:00 [running]> on host c37e8af922b1
[2025-02-25T02:26:01.168+0000] {taskinstance.py:2644} INFO - Exporting env vars: AIRFLOW_CTX_DAG_OWNER='***' AIRFLOW_CTX_DAG_ID='upload_bronze' AIRFLOW_CTX_TASK_ID='upload_bronze' AIRFLOW_CTX_EXECUTION_DATE='2025-02-25T02:00:32.574902+00:00' AIRFLOW_CTX_TRY_NUMBER='6' AIRFLOW_CTX_DAG_RUN_ID='manual__2025-02-25T02:00:32.574902+00:00'
[2025-02-25T02:26:01.170+0000] {taskinstance.py:430} INFO - ::endgroup::
[2025-02-25T02:26:01.175+0000] {taskinstance.py:441} INFO - ::group::Post task execution logs
[2025-02-25T02:26:01.176+0000] {taskinstance.py:2890} ERROR - Task failed with exception
Traceback (most recent call last):
  File "/home/airflow/.local/lib/python3.12/site-packages/airflow/models/taskinstance.py", line 465, in _execute_task
    result = _execute_callable(context=context, **execute_callable_kwargs)
             ^^^^^^^^^^^^^^^^^^^^^^^^^^^^^^^^^^^^^^^^^^^^^^^^^^^^^^^^^^^^^
  File "/home/airflow/.local/lib/python3.12/site-packages/airflow/models/taskinstance.py", line 432, in _execute_callable
    return execute_callable(context=context, **execute_callable_kwargs)
           ^^^^^^^^^^^^^^^^^^^^^^^^^^^^^^^^^^^^^^^^^^^^^^^^^^^^^^^^^^^^
  File "/home/airflow/.local/lib/python3.12/site-packages/airflow/models/baseoperator.py", line 400, in wrapper
    return func(self, *args, **kwargs)
           ^^^^^^^^^^^^^^^^^^^^^^^^^^^
  File "/home/airflow/.local/lib/python3.12/site-packages/airflow/operators/python.py", line 235, in execute
    return_value = self.execute_callable()
                   ^^^^^^^^^^^^^^^^^^^^^^^
  File "/home/airflow/.local/lib/python3.12/site-packages/airflow/operators/python.py", line 252, in execute_callable
    return self.python_callable(*self.op_args, **self.op_kwargs)
           ^^^^^^^^^^^^^^^^^^^^^^^^^^^^^^^^^^^^^^^^^^^^^^^^^^^^^
  File "/opt/airflow/dags/app/upload_bronze.py", line 8, in upload_bronze
    for file in os.listdir(INPUT_DIR):
                ^^^^^^^^^^^^^^^^^^^^^
FileNotFoundError: [Errno 2] No such file or directory: '/home/usuario/Documentos/Data sc/Des_5/RID-156732_Desafio08/Dados'
[2025-02-25T02:26:01.192+0000] {taskinstance.py:1205} INFO - Marking task as FAILED. dag_id=upload_bronze, task_id=upload_bronze, execution_date=20250225T020032, start_date=20250225T022600, end_date=20250225T022601
[2025-02-25T02:26:01.207+0000] {standard_task_runner.py:110} ERROR - Failed to execute job 95 for task upload_bronze ([Errno 2] No such file or directory: '/home/usuario/Documentos/Data sc/Des_5/RID-156732_Desafio08/Dados'; 1901)
[2025-02-25T02:26:01.237+0000] {local_task_job_runner.py:240} INFO - Task exited with return code 1
[2025-02-25T02:26:01.275+0000] {taskinstance.py:3482} INFO - 0 downstream tasks scheduled from follow-on schedule check
[2025-02-25T02:26:01.281+0000] {local_task_job_runner.py:222} INFO - ::endgroup::
