[2025-02-25T03:09:55.151+0000] {local_task_job_runner.py:120} INFO - ::group::Pre task execution logs
[2025-02-25T03:09:55.217+0000] {taskinstance.py:2073} INFO - Dependencies all met for dep_context=non-requeueable deps ti=<TaskInstance: upload_bronze.upload_bronze manual__2025-02-25T02:33:22.152134+00:00 [queued]>
[2025-02-25T03:09:55.250+0000] {taskinstance.py:2073} INFO - Dependencies all met for dep_context=requeueable deps ti=<TaskInstance: upload_bronze.upload_bronze manual__2025-02-25T02:33:22.152134+00:00 [queued]>
[2025-02-25T03:09:55.256+0000] {taskinstance.py:2303} INFO - Starting attempt 5 of 6
[2025-02-25T03:09:55.300+0000] {taskinstance.py:2327} INFO - Executing <Task(PythonOperator): upload_bronze> on 2025-02-25 02:33:22.152134+00:00
[2025-02-25T03:09:55.350+0000] {standard_task_runner.py:90} INFO - Running: ['***', 'tasks', 'run', 'upload_bronze', 'upload_bronze', 'manual__2025-02-25T02:33:22.152134+00:00', '--job-id', '139', '--raw', '--subdir', 'DAGS_FOLDER/Dag_des_5.py', '--cfg-path', '/tmp/tmp32ee6pzj']
[2025-02-25T03:09:55.340+0000] {warnings.py:110} WARNING - /home/***/.local/lib/python3.12/site-packages/***/task/task_runner/standard_task_runner.py:61: DeprecationWarning: This process (pid=233) is multi-threaded, use of fork() may lead to deadlocks in the child.
  pid = os.fork()

[2025-02-25T03:09:55.363+0000] {standard_task_runner.py:91} INFO - Job 139: Subtask upload_bronze
[2025-02-25T03:09:55.364+0000] {standard_task_runner.py:63} INFO - Started process 235 to run task
[2025-02-25T03:09:55.694+0000] {task_command.py:426} INFO - Running <TaskInstance: upload_bronze.upload_bronze manual__2025-02-25T02:33:22.152134+00:00 [running]> on host c37e8af922b1
[2025-02-25T03:09:55.920+0000] {taskinstance.py:2644} INFO - Exporting env vars: AIRFLOW_CTX_DAG_OWNER='***' AIRFLOW_CTX_DAG_ID='upload_bronze' AIRFLOW_CTX_TASK_ID='upload_bronze' AIRFLOW_CTX_EXECUTION_DATE='2025-02-25T02:33:22.152134+00:00' AIRFLOW_CTX_TRY_NUMBER='5' AIRFLOW_CTX_DAG_RUN_ID='manual__2025-02-25T02:33:22.152134+00:00'
[2025-02-25T03:09:55.925+0000] {taskinstance.py:430} INFO - ::endgroup::
[2025-02-25T03:09:55.927+0000] {taskinstance.py:441} INFO - ::group::Post task execution logs
[2025-02-25T03:09:55.929+0000] {taskinstance.py:2890} ERROR - Task failed with exception
Traceback (most recent call last):
  File "/home/airflow/.local/lib/python3.12/site-packages/airflow/models/taskinstance.py", line 465, in _execute_task
    result = _execute_callable(context=context, **execute_callable_kwargs)
             ^^^^^^^^^^^^^^^^^^^^^^^^^^^^^^^^^^^^^^^^^^^^^^^^^^^^^^^^^^^^^
  File "/home/airflow/.local/lib/python3.12/site-packages/airflow/models/taskinstance.py", line 432, in _execute_callable
    return execute_callable(context=context, **execute_callable_kwargs)
           ^^^^^^^^^^^^^^^^^^^^^^^^^^^^^^^^^^^^^^^^^^^^^^^^^^^^^^^^^^^^
  File "/home/airflow/.local/lib/python3.12/site-packages/airflow/models/baseoperator.py", line 400, in wrapper
    return func(self, *args, **kwargs)
           ^^^^^^^^^^^^^^^^^^^^^^^^^^^
  File "/home/airflow/.local/lib/python3.12/site-packages/airflow/operators/python.py", line 235, in execute
    return_value = self.execute_callable()
                   ^^^^^^^^^^^^^^^^^^^^^^^
  File "/home/airflow/.local/lib/python3.12/site-packages/airflow/operators/python.py", line 252, in execute_callable
    return self.python_callable(*self.op_args, **self.op_kwargs)
           ^^^^^^^^^^^^^^^^^^^^^^^^^^^^^^^^^^^^^^^^^^^^^^^^^^^^^
  File "/opt/airflow/dags/app/upload_bronze.py", line 8, in upload_bronze
    for file in os.listdir(INPUT_DIR):
                ^^^^^^^^^^^^^^^^^^^^^
FileNotFoundError: [Errno 2] No such file or directory: '/mnt/c/Users/Caio Mesquita/Desktop/Data sc/Des_5/RID-156732_Desafio08/Dados'
[2025-02-25T03:09:55.961+0000] {taskinstance.py:1205} INFO - Marking task as UP_FOR_RETRY. dag_id=upload_bronze, task_id=upload_bronze, execution_date=20250225T023322, start_date=20250225T030955, end_date=20250225T030955
[2025-02-25T03:09:55.993+0000] {standard_task_runner.py:110} ERROR - Failed to execute job 139 for task upload_bronze ([Errno 2] No such file or directory: '/mnt/c/Users/Caio Mesquita/Desktop/Data sc/Des_5/RID-156732_Desafio08/Dados'; 235)
[2025-02-25T03:09:56.023+0000] {local_task_job_runner.py:240} INFO - Task exited with return code 1
[2025-02-25T03:09:56.090+0000] {taskinstance.py:3482} INFO - 0 downstream tasks scheduled from follow-on schedule check
[2025-02-25T03:09:56.094+0000] {local_task_job_runner.py:222} INFO - ::endgroup::
