[2025-02-25T02:54:33.035+0000] {task_context_logger.py:104} WARNING - Marking task instance <TaskInstance: upload_bronze.upload_bronze manual__2025-02-25T02:33:22.152134+00:00 [queued]> stuck in queued as failed. If the task instance has available retries, it will be retried.
[2025-02-25T02:54:33.264+0000] {task_context_logger.py:104} ERROR - Executor reports task instance <TaskInstance: upload_bronze.upload_bronze manual__2025-02-25T02:33:22.152134+00:00 [queued]> finished (failed) although the task says it's queued. (Info: None) Was the task killed externally?
