[2025-02-24T04:25:22.114+0000] {task_context_logger.py:104} ERROR - Executor reports task instance <TaskInstance: upload_bronze.upload_bronze scheduled__2025-02-23T00:00:00+00:00 [queued]> finished (failed) although the task says it's queued. (Info: None) Was the task killed externally?
