[2025-02-25T02:36:45.168+0000] {task_context_logger.py:104} ERROR - Executor reports task instance <TaskInstance: upload_bronze.upload_bronze manual__2025-02-25T02:29:50.433540+00:00 [queued]> finished (failed) although the task says it's queued. (Info: None) Was the task killed externally?
